Workbook

Sheet Payroll
A1: MONTHLY PAYROLL — MALAYSIA
A2: Pay month: | B2: June 2026 | D2: Statutory contributions auto-calculated from the 'Rates' sheet.
A3: LEGEND: blue = you type it (inputs) black = auto-formula green = pulled from Rates sheet yellow = VERIFY against image
A4: EMP_ID | B4: Name | C4: Bank Name | D4: Bank Acct No | E4: Type | F4: Age >= 60? | G4: Apply EPF? | H4: Apply SOCSO +EIS? | I4: Basic | J4: Petrol Allow | K4: Incentive | L4: Dishwash Incentive | M4: Other Allow | N4: Work Days | O4: Unpaid Days | P4: OT Hours | Q4: OT Rate | R4: Other Deduct | S4: Extra PCB Relief/yr | T4: PCB Override | U4: Prorated Basic | V4: Gross (EPF wage) | W4: OT Pay | X4: Total Remun. | Y4: EPF Employee | Z4: EPF Employer | AA4: SOCSO Employee | AB4: SOCSO Employer | AC4: EIS Employee | AD4: EIS Employer | AE4: Charge. Income/yr | AF4: PCB Estimate | AG4: PCB Applied | AH4: Total EE Deduct | AI4: NET SALARY (take-home) | AJ4: Employer Statutory | AK4: EMPLOYER TOTAL COST
A5: ON00010 | B5: cheong fong cheng | C5: Cimb | D5: 7000986177 | E5: Permanent | F5: N | G5: Y | H5: Y | I5: 5000 | J5: 0 | K5: 0 | L5: 0 | M5: 0 | N5: 26 | O5: 0 | P5: 0 | Q5: 0 | R5: 0 | S5: 0 | U5: =IF(N5=0,I5,I5-O5*(I5/N5)) -> 5000 | V5: =U5+J5+K5+L5+M5 -> 5000 | W5: =P5*Q5 -> 0 | X5: =V5+W5 -> 5000 | Y5: =IF(G5="Y",ROUNDUP(V5*Rates!$B$5,0),0) -> 550 | Z5: =IF(G5="Y",ROUNDUP(V5*IF(X5>Rates!$B$8,Rates!$B$7,Rates!$B$6),0),0) -> 650 | AA5: =IF(H5="Y",IF(F5="Y",0,VLOOKUP(MIN(V5,Rates!$B$9),Rates!$A$34:$I$97,6,TRUE())),0) -> 24.75 | AB5: =IF(H5="Y",IF(F5="Y",VLOOKUP(MIN(V5,Rates!$B$9),Rates!$A$34:$I$97,8,TRUE()),VLOOKUP(MIN(V5,Rates!$B$9),Rates!$A$34:$I$97,7,TRUE())),0) -> 86.65 | AC5: =IF(AND(H5="Y",F5<>"Y"),VLOOKUP(MIN(V5,Rates!$B$9),Rates!$A$34:$I$97,9,TRUE()),0) -> 9.9 | AD5: =IF(AND(H5="Y",F5<>"Y"),VLOOKUP(MIN(V5,Rates!$B$9),Rates!$A$34:$I$97,9,TRUE()),0) -> 9.9 | AE5: =MAX(0,V5*12-Rates!$B$14-MIN(Y5*12,Rates!$B$15)-S5) -> 47000 | AF5: =MAX(0,MROUND((VLOOKUP(AE5,Rates!$A$21:$C$30,3,TRUE())+(AE5-VLOOKUP(AE5,Rates!$A$21:$C$30,1,TRUE()))*VLOOKUP(AE5,Rates!$A$21:$C$30,2,TRUE())-IF(AE5<=35000,Rates!$B$16,0))/12,0.05)) -> 110 | AG5: =IF(T5="",AF5,T5) -> 110 | AH5: =Y5+AA5+AC5+AG5+R5 -> 694.65 | AI5: =X5-AH5 -> 4305.35 | AJ5: =Z5+AB5+AD5 -> 746.55 | AK5: =X5+AJ5 -> 5746.55
A6: ON00011 | B6: mohd shah putra danial | C6: Maybank | D6: 112205095227 | E6: Permanent | F6: N | G6: Y | H6: Y | I6: 3200 | J6: 0 | K6: 0 | L6: 0 | M6: 0 | N6: 26 | O6: 0 | P6: 0 | Q6: 0 | R6: 0 | S6: 0 | U6: =IF(N6=0,I6,I6-O6*(I6/N6)) -> 3200 | V6: =U6+J6+K6+L6+M6 -> 3200 | W6: =P6*Q6 -> 0 | X6: =V6+W6 -> 3200 | Y6: =IF(G6="Y",ROUNDUP(V6*Rates!$B$5,0),0) -> 352 | Z6: =IF(G6="Y",ROUNDUP(V6*IF(X6>Rates!$B$8,Rates!$B$7,Rates!$B$6),0),0) -> 416 | AA6: =IF(H6="Y",IF(F6="Y",0,VLOOKUP(MIN(V6,Rates!$B$9),Rates!$A$34:$I$97,6,TRUE())),0) -> 15.75 | AB6: =IF(H6="Y",IF(F6="Y",VLOOKUP(MIN(V6,Rates!$B$9),Rates!$A$34:$I$97,8,TRUE()),VLOOKUP(MIN(V6,Rates!$B$9),Rates!$A$34:$I$97,7,TRUE())),0) -> 55.15 | AC6: =IF(AND(H6="Y",F6<>"Y"),VLOOKUP(MIN(V6,Rates!$B$9),Rates!$A$34:$I$97,9,TRUE()),0) -> 6.3 | AD6: =IF(AND(H6="Y",F6<>"Y"),VLOOKUP(MIN(V6,Rates!$B$9),Rates!$A$34:$I$97,9,TRUE()),0) -> 6.3 | AE6: =MAX(0,V6*12-Rates!$B$14-MIN(Y6*12,Rates!$B$15)-S6) -> 25400 | AF6: =MAX(0,MROUND((VLOOKUP(AE6,Rates!$A$21:$C$30,3,TRUE())+(AE6-VLOOKUP(AE6,Rates!$A$21:$C$30,1,TRUE()))*VLOOKUP(AE6,Rates!$A$21:$C$30,2,TRUE())-IF(AE6<=35000,Rates!$B$16,0))/12,0.05)) -> 0 | AG6: =IF(T6="",AF6,T6) -> 0 | AH6: =Y6+AA6+AC6+AG6+R6 -> 374.05 | AI6: =X6-AH6 -> 2825.95 | AJ6: =Z6+AB6+AD6 -> 477.45 | AK6: =X6+AJ6 -> 3677.45
A7: ON00012 | B7: mohd hafizal bin azahar | C7: Public Bank | D7: 4798247316 | E7: Permanent | F7: N | G7: Y | H7: Y | I7: 3000 | J7: 0 | K7: 200 | L7: 0 | M7: 0 | N7: 26 | O7: 0 | P7: 0 | Q7: 15 | R7: 0 | S7: 0 | U7: =IF(N7=0,I7,I7-O7*(I7/N7)) -> 3000 | V7: =U7+J7+K7+L7+M7 -> 3200 | W7: =P7*Q7 -> 0 | X7: =V7+W7 -> 3200 | Y7: =IF(G7="Y",ROUNDUP(V7*Rates!$B$5,0),0) -> 352 | Z7: =IF(G7="Y",ROUNDUP(V7*IF(X7>Rates!$B$8,Rates!$B$7,Rates!$B$6),0),0) -> 416 | AA7: =IF(H7="Y",IF(F7="Y",0,VLOOKUP(MIN(V7,Rates!$B$9),Rates!$A$34:$I$97,6,TRUE())),0) -> 15.75 | AB7: =IF(H7="Y",IF(F7="Y",VLOOKUP(MIN(V7,Rates!$B$9),Rates!$A$34:$I$97,8,TRUE()),VLOOKUP(MIN(V7,Rates!$B$9),Rates!$A$34:$I$97,7,TRUE())),0) -> 55.15 | AC7: =IF(AND(H7="Y",F7<>"Y"),VLOOKUP(MIN(V7,Rates!$B$9),Rates!$A$34:$I$97,9,TRUE()),0) -> 6.3 | AD7: =IF(AND(H7="Y",F7<>"Y"),VLOOKUP(MIN(V7,Rates!$B$9),Rates!$A$34:$I$97,9,TRUE()),0) -> 6.3 | AE7: =MAX(0,V7*12-Rates!$B$14-MIN(Y7*12,Rates!$B$15)-S7) -> 25400 | AF7: =MAX(0,MROUND((VLOOKUP(AE7,Rates!$A$21:$C$30,3,TRUE())+(AE7-VLOOKUP(AE7,Rates!$A$21:$C$30,1,TRUE()))*VLOOKUP(AE7,Rates!$A$21:$C$30,2,TRUE())-IF(AE7<=35000,Rates!$B$16,0))/12,0.05)) -> 0 | AG7: =IF(T7="",AF7,T7) -> 0 | AH7: =Y7+AA7+AC7+AG7+R7 -> 374.05 | AI7: =X7-AH7 -> 2825.95 | AJ7: =Z7+AB7+AD7 -> 477.45 | AK7: =X7+AJ7 -> 3677.45
A8: ON00013 | B8: Nur Azaharina Binti Azahar | C8: Bank Muamalat | D8: 3060002590765 | E8: Permanent | F8: N | G8: Y | H8: Y | I8: 2200 | J8: 0 | K8: 0 | L8: 0 | M8: 0 | N8: 26 | O8: 0 | P8: 0 | Q8: 0 | R8: 0 | S8: 0 | U8: =IF(N8=0,I8,I8-O8*(I8/N8)) -> 2200 | V8: =U8+J8+K8+L8+M8 -> 2200 | W8: =P8*Q8 -> 0 | X8: =V8+W8 -> 2200 | Y8: =IF(G8="Y",ROUNDUP(V8*Rates!$B$5,0),0) -> 242 | Z8: =IF(G8="Y",ROUNDUP(V8*IF(X8>Rates!$B$8,Rates!$B$7,Rates!$B$6),0),0) -> 286 | AA8: =IF(H8="Y",IF(F8="Y",0,VLOOKUP(MIN(V8,Rates!$B$9),Rates!$A$34:$I$97,6,TRUE())),0) -> 10.75 | AB8: =IF(H8="Y",IF(F8="Y",VLOOKUP(MIN(V8,Rates!$B$9),Rates!$A$34:$I$97,8,TRUE()),VLOOKUP(MIN(V8,Rates!$B$9),Rates!$A$34:$I$97,7,TRUE())),0) -> 37.65 | AC8: =IF(AND(H8="Y",F8<>"Y"),VLOOKUP(MIN(V8,Rates!$B$9),Rates!$A$34:$I$97,9,TRUE()),0) -> 4.3 | AD8: =IF(AND(H8="Y",F8<>"Y"),VLOOKUP(MIN(V8,Rates!$B$9),Rates!$A$34:$I$97,9,TRUE()),0) -> 4.3 | AE8: =MAX(0,V8*12-Rates!$B$14-MIN(Y8*12,Rates!$B$15)-S8) -> 14496 | AF8: =MAX(0,MROUND((VLOOKUP(AE8,Rates!$A$21:$C$30,3,TRUE())+(AE8-VLOOKUP(AE8,Rates!$A$21:$C$30,1,TRUE()))*VLOOKUP(AE8,Rates!$A$21:$C$30,2,TRUE())-IF(AE8<=35000,Rates!$B$16,0))/12,0.05)) -> 0 | AG8: =IF(T8="",AF8,T8) -> 0 | AH8: =Y8+AA8+AC8+AG8+R8 -> 257.05 | AI8: =X8-AH8 -> 1942.95 | AJ8: =Z8+AB8+AD8 -> 327.95 | AK8: =X8+AJ8 -> 2527.95
A9: ON00015 | B9: Chin Ching Hua | C9: Public Bank | D9: 5016571402 | E9: Permanent | F9: N | G9: Y | H9: Y | I9: 2200 | J9: 0 | K9: 0 | L9: 0 | M9: 0 | N9: 26 | O9: 0 | P9: 25.5 | Q9: 15 | R9: 0 | S9: 0 | U9: =IF(N9=0,I9,I9-O9*(I9/N9)) -> 2200 | V9: =U9+J9+K9+L9+M9 -> 2200 | W9: =P9*Q9 -> 382.5 | X9: =V9+W9 -> 2582.5 | Y9: =IF(G9="Y",ROUNDUP(V9*Rates!$B$5,0),0) -> 242 | Z9: =IF(G9="Y",ROUNDUP(V9*IF(X9>Rates!$B$8,Rates!$B$7,Rates!$B$6),0),0) -> 286 | AA9: =IF(H9="Y",IF(F9="Y",0,VLOOKUP(MIN(V9,Rates!$B$9),Rates!$A$34:$I$97,6,TRUE())),0) -> 10.75 | AB9: =IF(H9="Y",IF(F9="Y",VLOOKUP(MIN(V9,Rates!$B$9),Rates!$A$34:$I$97,8,TRUE()),VLOOKUP(MIN(V9,Rates!$B$9),Rates!$A$34:$I$97,7,TRUE())),0) -> 37.65 | AC9: =IF(AND(H9="Y",F9<>"Y"),VLOOKUP(MIN(V9,Rates!$B$9),Rates!$A$34:$I$97,9,TRUE()),0) -> 4.3 | AD9: =IF(AND(H9="Y",F9<>"Y"),VLOOKUP(MIN(V9,Rates!$B$9),Rates!$A$34:$I$97,9,TRUE()),0) -> 4.3 | AE9: =MAX(0,V9*12-Rates!$B$14-MIN(Y9*12,Rates!$B$15)-S9) -> 14496 | AF9: =MAX(0,MROUND((VLOOKUP(AE9,Rates!$A$21:$C$30,3,TRUE())+(AE9-VLOOKUP(AE9,Rates!$A$21:$C$30,1,TRUE()))*VLOOKUP(AE9,Rates!$A$21:$C$30,2,TRUE())-IF(AE9<=35000,Rates!$B$16,0))/12,0.05)) -> 0 | AG9: =IF(T9="",AF9,T9) -> 0 | AH9: =Y9+AA9+AC9+AG9+R9 -> 257.05 | AI9: =X9-AH9 -> 2325.45 | AJ9: =Z9+AB9+AD9 -> 327.95 | AK9: =X9+AJ9 -> 2910.45
A10: ON00022 | B10: Mohd Aminludin Bin Yahya | C10: Maybank | D10: 164061840677 | E10: Permanent | F10: N | G10: Y | H10: Y | I10: 2400 | J10: 0 | K10: 200 | L10: 0 | M10: 0 | N10: 26 | O10: 0 | P10: 22.5 | Q10: 15 | R10: 0 | S10: 0 | U10: =IF(N10=0,I10,I10-O10*(I10/N10)) -> 2400 | V10: =U10+J10+K10+L10+M10 -> 2600 | W10: =P10*Q10 -> 337.5 | X10: =V10+W10 -> 2937.5 | Y10: =IF(G10="Y",ROUNDUP(V10*Rates!$B$5,0),0) -> 286 | Z10: =IF(G10="Y",ROUNDUP(V10*IF(X10>Rates!$B$8,Rates!$B$7,Rates!$B$6),0),0) -> 338 | AA10: =IF(H10="Y",IF(F10="Y",0,VLOOKUP(MIN(V10,Rates!$B$9),Rates!$A$34:$I$97,6,TRUE())),0) -> 12.75 | AB10: =IF(H10="Y",IF(F10="Y",VLOOKUP(MIN(V10,Rates!$B$9),Rates!$A$34:$I$97,8,TRUE()),VLOOKUP(MIN(V10,Rates!$B$9),Rates!$A$34:$I$97,7,TRUE())),0) -> 44.65 | AC10: =IF(AND(H10="Y",F10<>"Y"),VLOOKUP(MIN(V10,Rates!$B$9),Rates!$A$34:$I$97,9,TRUE()),0) -> 5.1 | AD10: =IF(AND(H10="Y",F10<>"Y"),VLOOKUP(MIN(V10,Rates!$B$9),Rates!$A$34:$I$97,9,TRUE()),0) -> 5.1 | AE10: =MAX(0,V10*12-Rates!$B$14-MIN(Y10*12,Rates!$B$15)-S10) -> 18768 | AF10: =MAX(0,MROUND((VLOOKUP(AE10,Rates!$A$21:$C$30,3,TRUE())+(AE10-VLOOKUP(AE10,Rates!$A$21:$C$30,1,TRUE()))*VLOOKUP(AE10,Rates!$A$21:$C$30,2,TRUE())-IF(AE10<=35000,Rates!$B$16,0))/12,0.05)) -> 0 | AG10: =IF(T10="",AF10,T10) -> 0 | AH10: =Y10+AA10+AC10+AG10+R10 -> 303.85 | AI10: =X10-AH10 -> 2633.65 | AJ10: =Z10+AB10+AD10 -> 387.75 | AK10: =X10+AJ10 -> 3325.25
A11: ON00023 | B11: Nur Alya Adriana | C11: Maybank | D11: 564593318369 | E11: Permanent | F11: N | G11: Y | H11: Y | I11: 2100 | J11: 0 | K11: 0 | L11: 0 | M11: 0 | N11: 26 | O11: 0 | P11: 0 | Q11: 0 | R11: 0 | S11: 0 | U11: =IF(N11=0,I11,I11-O11*(I11/N11)) -> 2100 | V11: =U11+J11+K11+L11+M11 -> 2100 | W11: =P11*Q11 -> 0 | X11: =V11+W11 -> 2100 | Y11: =IF(G11="Y",ROUNDUP(V11*Rates!$B$5,0),0) -> 231 | Z11: =IF(G11="Y",ROUNDUP(V11*IF(X11>Rates!$B$8,Rates!$B$7,Rates!$B$6),0),0) -> 273 | AA11: =IF(H11="Y",IF(F11="Y",0,VLOOKUP(MIN(V11,Rates!$B$9),Rates!$A$34:$I$97,6,TRUE())),0) -> 10.25 | AB11: =IF(H11="Y",IF(F11="Y",VLOOKUP(MIN(V11,Rates!$B$9),Rates!$A$34:$I$97,8,TRUE()),VLOOKUP(MIN(V11,Rates!$B$9),Rates!$A$34:$I$97,7,TRUE())),0) -> 35.9 | AC11: =IF(AND(H11="Y",F11<>"Y"),VLOOKUP(MIN(V11,Rates!$B$9),Rates!$A$34:$I$97,9,TRUE()),0) -> 4.1 | AD11: =IF(AND(H11="Y",F11<>"Y"),VLOOKUP(MIN(V11,Rates!$B$9),Rates!$A$34:$I$97,9,TRUE()),0) -> 4.1 | AE11: =MAX(0,V11*12-Rates!$B$14-MIN(Y11*12,Rates!$B$15)-S11) -> 13428 | AF11: =MAX(0,MROUND((VLOOKUP(AE11,Rates!$A$21:$C$30,3,TRUE())+(AE11-VLOOKUP(AE11,Rates!$A$21:$C$30,1,TRUE()))*VLOOKUP(AE11,Rates!$A$21:$C$30,2,TRUE())-IF(AE11<=35000,Rates!$B$16,0))/12,0.05)) -> 0 | AG11: =IF(T11="",AF11,T11) -> 0 | AH11: =Y11+AA11+AC11+AG11+R11 -> 245.35 | AI11: =X11-AH11 -> 1854.65 | AJ11: =Z11+AB11+AD11 -> 313 | AK11: =X11+AJ11 -> 2413
A12: ON00028 | B12: Tan Kui Thean | C12: Maybank | D12: 164061854800 | E12: Permanent | F12: N | G12: Y | H12: Y | I12: 3200 | J12: 0 | K12: 0 | L12: 0 | M12: 0 | N12: 26 | O12: 0 | P12: 0 | Q12: 15 | R12: 0 | S12: 0 | U12: =IF(N12=0,I12,I12-O12*(I12/N12)) -> 3200 | V12: =U12+J12+K12+L12+M12 -> 3200 | W12: =P12*Q12 -> 0 | X12: =V12+W12 -> 3200 | Y12: =IF(G12="Y",ROUNDUP(V12*Rates!$B$5,0),0) -> 352 | Z12: =IF(G12="Y",ROUNDUP(V12*IF(X12>Rates!$B$8,Rates!$B$7,Rates!$B$6),0),0) -> 416 | AA12: =IF(H12="Y",IF(F12="Y",0,VLOOKUP(MIN(V12,Rates!$B$9),Rates!$A$34:$I$97,6,TRUE())),0) -> 15.75 | AB12: =IF(H12="Y",IF(F12="Y",VLOOKUP(MIN(V12,Rates!$B$9),Rates!$A$34:$I$97,8,TRUE()),VLOOKUP(MIN(V12,Rates!$B$9),Rates!$A$34:$I$97,7,TRUE())),0) -> 55.15 | AC12: =IF(AND(H12="Y",F12<>"Y"),VLOOKUP(MIN(V12,Rates!$B$9),Rates!$A$34:$I$97,9,TRUE()),0) -> 6.3 | AD12: =IF(AND(H12="Y",F12<>"Y"),VLOOKUP(MIN(V12,Rates!$B$9),Rates!$A$34:$I$97,9,TRUE()),0) -> 6.3 | AE12: =MAX(0,V12*12-Rates!$B$14-MIN(Y12*12,Rates!$B$15)-S12) -> 25400 | AF12: =MAX(0,MROUND((VLOOKUP(AE12,Rates!$A$21:$C$30,3,TRUE())+(AE12-VLOOKUP(AE12,Rates!$A$21:$C$30,1,TRUE()))*VLOOKUP(AE12,Rates!$A$21:$C$30,2,TRUE())-IF(AE12<=35000,Rates!$B$16,0))/12,0.05)) -> 0 | AG12: =IF(T12="",AF12,T12) -> 0 | AH12: =Y12+AA12+AC12+AG12+R12 -> 374.05 | AI12: =X12-AH12 -> 2825.95 | AJ12: =Z12+AB12+AD12 -> 477.45 | AK12: =X12+AJ12 -> 3677.45
A13: ON00030 | B13: HOU CHING | C13: Public Bank | D13: 5102691912 | E13: Part-time | F13: N | G13: N | H13: N | I13: 0 | J13: 0 | K13: 0 | L13: 0 | M13: 0 | N13: 26 | O13: 0 | P13: 0 | Q13: 8 | R13: 0 | S13: 0 | U13: =IF(N13=0,I13,I13-O13*(I13/N13)) -> 0 | V13: =U13+J13+K13+L13+M13 -> 0 | W13: =P13*Q13 -> 0 | X13: =V13+W13 -> 0 | Y13: =IF(G13="Y",ROUNDUP(V13*Rates!$B$5,0),0) -> 0 | Z13: =IF(G13="Y",ROUNDUP(V13*IF(X13>Rates!$B$8,Rates!$B$7,Rates!$B$6),0),0) -> 0 | AA13: =IF(H13="Y",IF(F13="Y",0,VLOOKUP(MIN(V13,Rates!$B$9),Rates!$A$34:$I$97,6,TRUE())),0) -> 0 | AB13: =IF(H13="Y",IF(F13="Y",VLOOKUP(MIN(V13,Rates!$B$9),Rates!$A$34:$I$97,8,TRUE()),VLOOKUP(MIN(V13,Rates!$B$9),Rates!$A$34:$I$97,7,TRUE())),0) -> 0 | AC13: =IF(AND(H13="Y",F13<>"Y"),VLOOKUP(MIN(V13,Rates!$B$9),Rates!$A$34:$I$97,9,TRUE()),0) -> 0 | AD13: =IF(AND(H13="Y",F13<>"Y"),VLOOKUP(MIN(V13,Rates!$B$9),Rates!$A$34:$I$97,9,TRUE()),0) -> 0 | AE13: =MAX(0,V13*12-Rates!$B$14-MIN(Y13*12,Rates!$B$15)-S13) -> 0 | AF13: =MAX(0,MROUND((VLOOKUP(AE13,Rates!$A$21:$C$30,3,TRUE())+(AE13-VLOOKUP(AE13,Rates!$A$21:$C$30,1,TRUE()))*VLOOKUP(AE13,Rates!$A$21:$C$30,2,TRUE())-IF(AE13<=35000,Rates!$B$16,0))/12,0.05)) -> 0 | AG13: =IF(T13="",AF13,T13) -> 0 | AH13: =Y13+AA13+AC13+AG13+R13 -> 0 | AI13: =X13-AH13 -> 0 | AJ13: =Z13+AB13+AD13 -> 0 | AK13: =X13+AJ13 -> 0
A14: ON00031 | B14: Aron cheng Eng | C14: Cimb | D14: 7657001861 | E14: Part-time | F14: N | G14: N | H14: N | I14: 0 | J14: 0 | K14: 0 | L14: 0 | M14: 0 | N14: 26 | O14: 0 | P14: 0 | Q14: 8 | R14: 0 | S14: 0 | U14: =IF(N14=0,I14,I14-O14*(I14/N14)) -> 0 | V14: =U14+J14+K14+L14+M14 -> 0 | W14: =P14*Q14 -> 0 | X14: =V14+W14 -> 0 | Y14: =IF(G14="Y",ROUNDUP(V14*Rates!$B$5,0),0) -> 0 | Z14: =IF(G14="Y",ROUNDUP(V14*IF(X14>Rates!$B$8,Rates!$B$7,Rates!$B$6),0),0) -> 0 | AA14: =IF(H14="Y",IF(F14="Y",0,VLOOKUP(MIN(V14,Rates!$B$9),Rates!$A$34:$I$97,6,TRUE())),0) -> 0 | AB14: =IF(H14="Y",IF(F14="Y",VLOOKUP(MIN(V14,Rates!$B$9),Rates!$A$34:$I$97,8,TRUE()),VLOOKUP(MIN(V14,Rates!$B$9),Rates!$A$34:$I$97,7,TRUE())),0) -> 0 | AC14: =IF(AND(H14="Y",F14<>"Y"),VLOOKUP(MIN(V14,Rates!$B$9),Rates!$A$34:$I$97,9,TRUE()),0) -> 0 | AD14: =IF(AND(H14="Y",F14<>"Y"),VLOOKUP(MIN(V14,Rates!$B$9),Rates!$A$34:$I$97,9,TRUE()),0) -> 0 | AE14: =MAX(0,V14*12-Rates!$B$14-MIN(Y14*12,Rates!$B$15)-S14) -> 0 | AF14: =MAX(0,MROUND((VLOOKUP(AE14,Rates!$A$21:$C$30,3,TRUE())+(AE14-VLOOKUP(AE14,Rates!$A$21:$C$30,1,TRUE()))*VLOOKUP(AE14,Rates!$A$21:$C$30,2,TRUE())-IF(AE14<=35000,Rates!$B$16,0))/12,0.05)) -> 0 | AG14: =IF(T14="",AF14,T14) -> 0 | AH14: =Y14+AA14+AC14+AG14+R14 -> 0 | AI14: =X14-AH14 -> 0 | AJ14: =Z14+AB14+AD14 -> 0 | AK14: =X14+AJ14 -> 0
B15: Liew Chen Hao | C15: Cimb | E15: Part-time | F15: N | G15: N | H15: N | I15: 0 | J15: 0 | K15: 0 | L15: 0 | M15: 0 | N15: 26 | O15: 0 | P15: 51 | Q15: 8 | R15: 0 | S15: 0 | U15: =IF(N15=0,I15,I15-O15*(I15/N15)) -> 0 | V15: =U15+J15+K15+L15+M15 -> 0 | W15: =P15*Q15 -> 408 | X15: =V15+W15 -> 408 | Y15: =IF(G15="Y",ROUNDUP(V15*Rates!$B$5,0),0) -> 0 | Z15: =IF(G15="Y",ROUNDUP(V15*IF(X15>Rates!$B$8,Rates!$B$7,Rates!$B$6),0),0) -> 0 | AA15: =IF(H15="Y",IF(F15="Y",0,VLOOKUP(MIN(V15,Rates!$B$9),Rates!$A$34:$I$97,6,TRUE())),0) -> 0 | AB15: =IF(H15="Y",IF(F15="Y",VLOOKUP(MIN(V15,Rates!$B$9),Rates!$A$34:$I$97,8,TRUE()),VLOOKUP(MIN(V15,Rates!$B$9),Rates!$A$34:$I$97,7,TRUE())),0) -> 0 | AC15: =IF(AND(H15="Y",F15<>"Y"),VLOOKUP(MIN(V15,Rates!$B$9),Rates!$A$34:$I$97,9,TRUE()),0) -> 0 | AD15: =IF(AND(H15="Y",F15<>"Y"),VLOOKUP(MIN(V15,Rates!$B$9),Rates!$A$34:$I$97,9,TRUE()),0) -> 0 | AE15: =MAX(0,V15*12-Rates!$B$14-MIN(Y15*12,Rates!$B$15)-S15) -> 0 | AF15: =MAX(0,MROUND((VLOOKUP(AE15,Rates!$A$21:$C$30,3,TRUE())+(AE15-VLOOKUP(AE15,Rates!$A$21:$C$30,1,TRUE()))*VLOOKUP(AE15,Rates!$A$21:$C$30,2,TRUE())-IF(AE15<=35000,Rates!$B$16,0))/12,0.05)) -> 0 | AG15: =IF(T15="",AF15,T15) -> 0 | AH15: =Y15+AA15+AC15+AG15+R15 -> 0 | AI15: =X15-AH15 -> 408 | AJ15: =Z15+AB15+AD15 -> 0 | AK15: =X15+AJ15 -> 408
B16: Tai Jun Xi | C16: Cash | E16: Part-time | F16: N | G16: N | H16: N | I16: 0 | J16: 0 | K16: 0 | L16: 0 | M16: 0 | N16: 26 | O16: 0 | P16: 41 | Q16: 8 | R16: 0 | S16: 0 | U16: =IF(N16=0,I16,I16-O16*(I16/N16)) -> 0 | V16: =U16+J16+K16+L16+M16 -> 0 | W16: =P16*Q16 -> 328 | X16: =V16+W16 -> 328 | Y16: =IF(G16="Y",ROUNDUP(V16*Rates!$B$5,0),0) -> 0 | Z16: =IF(G16="Y",ROUNDUP(V16*IF(X16>Rates!$B$8,Rates!$B$7,Rates!$B$6),0),0) -> 0 | AA16: =IF(H16="Y",IF(F16="Y",0,VLOOKUP(MIN(V16,Rates!$B$9),Rates!$A$34:$I$97,6,TRUE())),0) -> 0 | AB16: =IF(H16="Y",IF(F16="Y",VLOOKUP(MIN(V16,Rates!$B$9),Rates!$A$34:$I$97,8,TRUE()),VLOOKUP(MIN(V16,Rates!$B$9),Rates!$A$34:$I$97,7,TRUE())),0) -> 0 | AC16: =IF(AND(H16="Y",F16<>"Y"),VLOOKUP(MIN(V16,Rates!$B$9),Rates!$A$34:$I$97,9,TRUE()),0) -> 0 | AD16: =IF(AND(H16="Y",F16<>"Y"),VLOOKUP(MIN(V16,Rates!$B$9),Rates!$A$34:$I$97,9,TRUE()),0) -> 0 | AE16: =MAX(0,V16*12-Rates!$B$14-MIN(Y16*12,Rates!$B$15)-S16) -> 0 | AF16: =MAX(0,MROUND((VLOOKUP(AE16,Rates!$A$21:$C$30,3,TRUE())+(AE16-VLOOKUP(AE16,Rates!$A$21:$C$30,1,TRUE()))*VLOOKUP(AE16,Rates!$A$21:$C$30,2,TRUE())-IF(AE16<=35000,Rates!$B$16,0))/12,0.05)) -> 0 | AG16: =IF(T16="",AF16,T16) -> 0 | AH16: =Y16+AA16+AC16+AG16+R16 -> 0 | AI16: =X16-AH16 -> 328 | AJ16: =Z16+AB16+AD16 -> 0 | AK16: =X16+AJ16 -> 328
A17: ON00055 | B17: Nay Lin Zaw | C17: Merchantrade | D17: 500001618970 | E17: Part-time | F17: N | G17: N | H17: N | I17: 2300 | J17: 0 | K17: 0 | L17: 0 | M17: 0 | N17: 26 | O17: 0 | P17: 0 | Q17: 0 | R17: 0 | S17: 0 | U17: =IF(N17=0,I17,I17-O17*(I17/N17)) -> 2300 | V17: =U17+J17+K17+L17+M17 -> 2300 | W17: =P17*Q17 -> 0 | X17: =V17+W17 -> 2300 | Y17: =IF(G17="Y",ROUNDUP(V17*Rates!$B$5,0),0) -> 0 | Z17: =IF(G17="Y",ROUNDUP(V17*IF(X17>Rates!$B$8,Rates!$B$7,Rates!$B$6),0),0) -> 0 | AA17: =IF(H17="Y",IF(F17="Y",0,VLOOKUP(MIN(V17,Rates!$B$9),Rates!$A$34:$I$97,6,TRUE())),0) -> 0 | AB17: =IF(H17="Y",IF(F17="Y",VLOOKUP(MIN(V17,Rates!$B$9),Rates!$A$34:$I$97,8,TRUE()),VLOOKUP(MIN(V17,Rates!$B$9),Rates!$A$34:$I$97,7,TRUE())),0) -> 0 | AC17: =IF(AND(H17="Y",F17<>"Y"),VLOOKUP(MIN(V17,Rates!$B$9),Rates!$A$34:$I$97,9,TRUE()),0) -> 0 | AD17: =IF(AND(H17="Y",F17<>"Y"),VLOOKUP(MIN(V17,Rates!$B$9),Rates!$A$34:$I$97,9,TRUE()),0) -> 0 | AE17: =MAX(0,V17*12-Rates!$B$14-MIN(Y17*12,Rates!$B$15)-S17) -> 18600 | AF17: =MAX(0,MROUND((VLOOKUP(AE17,Rates!$A$21:$C$30,3,TRUE())+(AE17-VLOOKUP(AE17,Rates!$A$21:$C$30,1,TRUE()))*VLOOKUP(AE17,Rates!$A$21:$C$30,2,TRUE())-IF(AE17<=35000,Rates!$B$16,0))/12,0.05)) -> 0 | AG17: =IF(T17="",AF17,T17) -> 0 | AH17: =Y17+AA17+AC17+AG17+R17 -> 0 | AI17: =X17-AH17 -> 2300 | AJ17: =Z17+AB17+AD17 -> 0 | AK17: =X17+AJ17 -> 2300
B18: Ong Peir Ann | C18: Public Bank | D18: 5097798113 | E18: Part-time | F18: N | G18: N | H18: N | I18: 0 | J18: 0 | K18: 0 | L18: 0 | M18: 0 | N18: 26 | O18: 0 | P18: 210 | Q18: 8 | R18: 0 | S18: 0 | U18: =IF(N18=0,I18,I18-O18*(I18/N18)) -> 0 | V18: =U18+J18+K18+L18+M18 -> 0 | W18: =P18*Q18 -> 1680 | X18: =V18+W18 -> 1680 | Y18: =IF(G18="Y",ROUNDUP(V18*Rates!$B$5,0),0) -> 0 | Z18: =IF(G18="Y",ROUNDUP(V18*IF(X18>Rates!$B$8,Rates!$B$7,Rates!$B$6),0),0) -> 0 | AA18: =IF(H18="Y",IF(F18="Y",0,VLOOKUP(MIN(V18,Rates!$B$9),Rates!$A$34:$I$97,6,TRUE())),0) -> 0 | AB18: =IF(H18="Y",IF(F18="Y",VLOOKUP(MIN(V18,Rates!$B$9),Rates!$A$34:$I$97,8,TRUE()),VLOOKUP(MIN(V18,Rates!$B$9),Rates!$A$34:$I$97,7,TRUE())),0) -> 0 | AC18: =IF(AND(H18="Y",F18<>"Y"),VLOOKUP(MIN(V18,Rates!$B$9),Rates!$A$34:$I$97,9,TRUE()),0) -> 0 | AD18: =IF(AND(H18="Y",F18<>"Y"),VLOOKUP(MIN(V18,Rates!$B$9),Rates!$A$34:$I$97,9,TRUE()),0) -> 0 | AE18: =MAX(0,V18*12-Rates!$B$14-MIN(Y18*12,Rates!$B$15)-S18) -> 0 | AF18: =MAX(0,MROUND((VLOOKUP(AE18,Rates!$A$21:$C$30,3,TRUE())+(AE18-VLOOKUP(AE18,Rates!$A$21:$C$30,1,TRUE()))*VLOOKUP(AE18,Rates!$A$21:$C$30,2,TRUE())-IF(AE18<=35000,Rates!$B$16,0))/12,0.05)) -> 0 | AG18: =IF(T18="",AF18,T18) -> 0 | AH18: =Y18+AA18+AC18+AG18+R18 -> 0 | AI18: =X18-AH18 -> 1680 | AJ18: =Z18+AB18+AD18 -> 0 | AK18: =X18+AJ18 -> 1680
B19: Thulasi Raj | C19: Cimb | D19: 7651498174 | E19: Part-time | F19: N | G19: N | H19: N | I19: 0 | J19: 0 | K19: 0 | L19: 0 | M19: 0 | N19: 26 | O19: 0 | P19: 4 | Q19: 8 | R19: 0 | S19: 0 | U19: =IF(N19=0,I19,I19-O19*(I19/N19)) -> 0 | V19: =U19+J19+K19+L19+M19 -> 0 | W19: =P19*Q19 -> 32 | X19: =V19+W19 -> 32 | Y19: =IF(G19="Y",ROUNDUP(V19*Rates!$B$5,0),0) -> 0 | Z19: =IF(G19="Y",ROUNDUP(V19*IF(X19>Rates!$B$8,Rates!$B$7,Rates!$B$6),0),0) -> 0 | AA19: =IF(H19="Y",IF(F19="Y",0,VLOOKUP(MIN(V19,Rates!$B$9),Rates!$A$34:$I$97,6,TRUE())),0) -> 0 | AB19: =IF(H19="Y",IF(F19="Y",VLOOKUP(MIN(V19,Rates!$B$9),Rates!$A$34:$I$97,8,TRUE()),VLOOKUP(MIN(V19,Rates!$B$9),Rates!$A$34:$I$97,7,TRUE())),0) -> 0 | AC19: =IF(AND(H19="Y",F19<>"Y"),VLOOKUP(MIN(V19,Rates!$B$9),Rates!$A$34:$I$97,9,TRUE()),0) -> 0 | AD19: =IF(AND(H19="Y",F19<>"Y"),VLOOKUP(MIN(V19,Rates!$B$9),Rates!$A$34:$I$97,9,TRUE()),0) -> 0 | AE19: =MAX(0,V19*12-Rates!$B$14-MIN(Y19*12,Rates!$B$15)-S19) -> 0 | AF19: =MAX(0,MROUND((VLOOKUP(AE19,Rates!$A$21:$C$30,3,TRUE())+(AE19-VLOOKUP(AE19,Rates!$A$21:$C$30,1,TRUE()))*VLOOKUP(AE19,Rates!$A$21:$C$30,2,TRUE())-IF(AE19<=35000,Rates!$B$16,0))/12,0.05)) -> 0 | AG19: =IF(T19="",AF19,T19) -> 0 | AH19: =Y19+AA19+AC19+AG19+R19 -> 0 | AI19: =X19-AH19 -> 32 | AJ19: =Z19+AB19+AD19 -> 0 | AK19: =X19+AJ19 -> 32
B20: Shannen Marie Gomez | C20: Maybank | E20: Part-time | F20: N | G20: N | H20: N | I20: 0 | J20: 0 | K20: 0 | L20: 0 | M20: 0 | N20: 26 | O20: 0 | P20: 7 | Q20: 8 | R20: 0 | S20: 0 | U20: =IF(N20=0,I20,I20-O20*(I20/N20)) -> 0 | V20: =U20+J20+K20+L20+M20 -> 0 | W20: =P20*Q20 -> 56 | X20: =V20+W20 -> 56 | Y20: =IF(G20="Y",ROUNDUP(V20*Rates!$B$5,0),0) -> 0 | Z20: =IF(G20="Y",ROUNDUP(V20*IF(X20>Rates!$B$8,Rates!$B$7,Rates!$B$6),0),0) -> 0 | AA20: =IF(H20="Y",IF(F20="Y",0,VLOOKUP(MIN(V20,Rates!$B$9),Rates!$A$34:$I$97,6,TRUE())),0) -> 0 | AB20: =IF(H20="Y",IF(F20="Y",VLOOKUP(MIN(V20,Rates!$B$9),Rates!$A$34:$I$97,8,TRUE()),VLOOKUP(MIN(V20,Rates!$B$9),Rates!$A$34:$I$97,7,TRUE())),0) -> 0 | AC20: =IF(AND(H20="Y",F20<>"Y"),VLOOKUP(MIN(V20,Rates!$B$9),Rates!$A$34:$I$97,9,TRUE()),0) -> 0 | AD20: =IF(AND(H20="Y",F20<>"Y"),VLOOKUP(MIN(V20,Rates!$B$9),Rates!$A$34:$I$97,9,TRUE()),0) -> 0 | AE20: =MAX(0,V20*12-Rates!$B$14-MIN(Y20*12,Rates!$B$15)-S20) -> 0 | AF20: =MAX(0,MROUND((VLOOKUP(AE20,Rates!$A$21:$C$30,3,TRUE())+(AE20-VLOOKUP(AE20,Rates!$A$21:$C$30,1,TRUE()))*VLOOKUP(AE20,Rates!$A$21:$C$30,2,TRUE())-IF(AE20<=35000,Rates!$B$16,0))/12,0.05)) -> 0 | AG20: =IF(T20="",AF20,T20) -> 0 | AH20: =Y20+AA20+AC20+AG20+R20 -> 0 | AI20: =X20-AH20 -> 56 | AJ20: =Z20+AB20+AD20 -> 0 | AK20: =X20+AJ20 -> 56
B21: Soh Jia Mon | C21: Public Bank | D21: 5089470408 | E21: Part-time | F21: N | G21: N | H21: N | I21: 0 | J21: 0 | K21: 0 | L21: 0 | M21: 0 | N21: 26 | O21: 0 | P21: 28 | Q21: 8 | R21: 0 | S21: 0 | U21: =IF(N21=0,I21,I21-O21*(I21/N21)) -> 0 | V21: =U21+J21+K21+L21+M21 -> 0 | W21: =P21*Q21 -> 224 | X21: =V21+W21 -> 224 | Y21: =IF(G21="Y",ROUNDUP(V21*Rates!$B$5,0),0) -> 0 | Z21: =IF(G21="Y",ROUNDUP(V21*IF(X21>Rates!$B$8,Rates!$B$7,Rates!$B$6),0),0) -> 0 | AA21: =IF(H21="Y",IF(F21="Y",0,VLOOKUP(MIN(V21,Rates!$B$9),Rates!$A$34:$I$97,6,TRUE())),0) -> 0 | AB21: =IF(H21="Y",IF(F21="Y",VLOOKUP(MIN(V21,Rates!$B$9),Rates!$A$34:$I$97,8,TRUE()),VLOOKUP(MIN(V21,Rates!$B$9),Rates!$A$34:$I$97,7,TRUE())),0) -> 0 | AC21: =IF(AND(H21="Y",F21<>"Y"),VLOOKUP(MIN(V21,Rates!$B$9),Rates!$A$34:$I$97,9,TRUE()),0) -> 0 | AD21: =IF(AND(H21="Y",F21<>"Y"),VLOOKUP(MIN(V21,Rates!$B$9),Rates!$A$34:$I$97,9,TRUE()),0) -> 0 | AE21: =MAX(0,V21*12-Rates!$B$14-MIN(Y21*12,Rates!$B$15)-S21) -> 0 | AF21: =MAX(0,MROUND((VLOOKUP(AE21,Rates!$A$21:$C$30,3,TRUE())+(AE21-VLOOKUP(AE21,Rates!$A$21:$C$30,1,TRUE()))*VLOOKUP(AE21,Rates!$A$21:$C$30,2,TRUE())-IF(AE21<=35000,Rates!$B$16,0))/12,0.05)) -> 0 | AG21: =IF(T21="",AF21,T21) -> 0 | AH21: =Y21+AA21+AC21+AG21+R21 -> 0 | AI21: =X21-AH21 -> 224 | AJ21: =Z21+AB21+AD21 -> 0 | AK21: =X21+AJ21 -> 224
B22: Chee Wei Hong | C22: Maybank | E22: Part-time | F22: N | G22: N | H22: N | I22: 0 | J22: 0 | K22: 0 | L22: 0 | M22: 0 | N22: 26 | O22: 0 | P22: 87 | Q22: 8 | R22: 0 | S22: 0 | U22: =IF(N22=0,I22,I22-O22*(I22/N22)) -> 0 | V22: =U22+J22+K22+L22+M22 -> 0 | W22: =P22*Q22 -> 696 | X22: =V22+W22 -> 696 | Y22: =IF(G22="Y",ROUNDUP(V22*Rates!$B$5,0),0) -> 0 | Z22: =IF(G22="Y",ROUNDUP(V22*IF(X22>Rates!$B$8,Rates!$B$7,Rates!$B$6),0),0) -> 0 | AA22: =IF(H22="Y",IF(F22="Y",0,VLOOKUP(MIN(V22,Rates!$B$9),Rates!$A$34:$I$97,6,TRUE())),0) -> 0 | AB22: =IF(H22="Y",IF(F22="Y",VLOOKUP(MIN(V22,Rates!$B$9),Rates!$A$34:$I$97,8,TRUE()),VLOOKUP(MIN(V22,Rates!$B$9),Rates!$A$34:$I$97,7,TRUE())),0) -> 0 | AC22: =IF(AND(H22="Y",F22<>"Y"),VLOOKUP(MIN(V22,Rates!$B$9),Rates!$A$34:$I$97,9,TRUE()),0) -> 0 | AD22: =IF(AND(H22="Y",F22<>"Y"),VLOOKUP(MIN(V22,Rates!$B$9),Rates!$A$34:$I$97,9,TRUE()),0) -> 0 | AE22: =MAX(0,V22*12-Rates!$B$14-MIN(Y22*12,Rates!$B$15)-S22) -> 0 | AF22: =MAX(0,MROUND((VLOOKUP(AE22,Rates!$A$21:$C$30,3,TRUE())+(AE22-VLOOKUP(AE22,Rates!$A$21:$C$30,1,TRUE()))*VLOOKUP(AE22,Rates!$A$21:$C$30,2,TRUE())-IF(AE22<=35000,Rates!$B$16,0))/12,0.05)) -> 0 | AG22: =IF(T22="",AF22,T22) -> 0 | AH22: =Y22+AA22+AC22+AG22+R22 -> 0 | AI22: =X22-AH22 -> 696 | AJ22: =Z22+AB22+AD22 -> 0 | AK22: =X22+AJ22 -> 696
A23: TOTALS | I23: =SUM(I5:I22) -> 25600 | J23: =SUM(J5:J22) -> 0 | K23: =SUM(K5:K22) -> 400 | L23: =SUM(L5:L22) -> 0 | M23: =SUM(M5:M22) -> 0 | R23: =SUM(R5:R22) -> 0 | U23: =SUM(U5:U22) -> 25600 | V23: =SUM(V5:V22) -> 26000 | W23: =SUM(W5:W22) -> 4144 | X23: =SUM(X5:X22) -> 30144 | Y23: =SUM(Y5:Y22) -> 2607 | Z23: =SUM(Z5:Z22) -> 3081 | AA23: =SUM(AA5:AA22) -> 116.5 | AB23: =SUM(AB5:AB22) -> 407.95 | ... AK23: =SUM(AK5:AK22) -> 33679.55

Sheet Rates
A1: STATUTORY RATES & CONTRIBUTION TABLES — MALAYSIA
A2: Effective rates: EPF (KWSP), SOCSO/EIS (PERKESO) ceiling RM6,000 from 1 Oct 2024, PCB brackets YA2024/2025. Edit the yellow parameter cells if rates change.
A4: PARAMETER | B4: VALUE | C4: NOTES
A5: EPF employee rate | B5: 0.11 | C5: Malaysian/PR under 60
A6: EPF employer rate (wage <= threshold) | B6: 0.13 | C6: 13% for wages up to RM5,000
A7: EPF employer rate (wage > threshold) | B7: 0.12 | C7: 12% for wages above RM5,000
A8: EPF employer threshold (RM) | B8: 5000 | C8: Total monthly remuneration test
A9: SOCSO / EIS wage ceiling (RM) | B9: 6000 | C9: Contribution capped at this wage
A10: SOCSO Cat 1 employee % | B10: 0.005 | C10: Injury + Invalidity (age < 60)
A11: SOCSO Cat 1 employer % | B11: 0.0175 | C11: Injury + Invalidity (age < 60)
A12: SOCSO Cat 2 employer % | B12: 0.0125 | C12: Injury only (age >= 60)
A13: EIS rate (each side) % | B13: 0.002 | C13: Employer & employee, age 18-60
A14: PCB personal relief (RM/yr) | B14: 9000 | C14: Self
A15: PCB EPF+life relief cap (RM/yr) | B15: 4000 | C15: EPF portion of the RM7,000 cap
A16: PCB rebate if chargeable <= RM35,000 | B16: 400 | C16: Section 6A individual rebate
A17: Default working days / month | B17: 26 | C17: Used for unpaid-leave proration
A19: RESIDENT INCOME-TAX BRACKETS (YA2024/2025) — used for PCB estimate
A20: Chargeable from (RM) | B20: Marginal rate | C20: Cumulative tax at 'from' (RM)
A21: 0 | B21: 0 | C21: 0
A22: 5000 | B22: 0.01 | C22: 0
A23: 20000 | B23: 0.03 | C23: 150
A24: 35000 | B24: 0.06 | C24: 600
A25: 50000 | B25: 0.11 | C25: 1500
A26: 70000 | B26: 0.19 | C26: 3700
A27: 100000 | B27: 0.25 | C27: 9400
A28: 400000 | B28: 0.26 | C28: 84400
A29: 600000 | B29: 0.28 | C29: 136400
A30: 2000000 | B30: 0.3 | C30: 528400
A32: SOCSO (PERKESO) + EIS CONTRIBUTION TABLE — RM100 bands, ceiling RM6,000
A33: Key (>=) | B33: Wage band (RM) | C33: Lower | D33: Upper | E33: Assumed wage | F33: SOCSO C1 employee | G33: SOCSO C1 employer | H33: SOCSO C2 employer | I33: EIS (each)
A34: 0 | B34: 0.01 - 30.00 | C34: 0 | D34: 30 | E34: =(C34+D34)/2 -> 15 | F34: =MROUND(Rates!$B$10*E34,0.05) -> 0.1 | G34: =MROUND(Rates!$B$11*E34,0.05) -> 0.25 | H34: =MROUND(Rates!$B$12*E34,0.05) -> 0.2 | I34: =MROUND(Rates!$B$13*E34,0.05) -> 0.05
A35: 30.01 | B35: 30.01 - 50.00 | C35: 30 | D35: 50 | E35: =(C35+D35)/2 -> 40 | F35: =MROUND(Rates!$B$10*E35,0.05) -> 0.2 | G35: =MROUND(Rates!$B$11*E35,0.05) -> 0.7 | H35: =MROUND(Rates!$B$12*E35,0.05) -> 0.5 | I35: =MROUND(Rates!$B$13*E35,0.05) -> 0.1
A36: 50.01 | B36: 50.01 - 70.00 | C36: 50 | D36: 70 | E36: =(C36+D36)/2 -> 60 | F36: =MROUND(Rates!$B$10*E36,0.05) -> 0.3 | G36: =MROUND(Rates!$B$11*E36,0.05) -> 1.05 | H36: =MROUND(Rates!$B$12*E36,0.05) -> 0.75 | I36: =MROUND(Rates!$B$13*E36,0.05) -> 0.1
A37: 70.01 | B37: 70.01 - 100.00 | C37: 70 | D37: 100 | E37: =(C37+D37)/2 -> 85 | F37: =MROUND(Rates!$B$10*E37,0.05) -> 0.45 | G37: =MROUND(Rates!$B$11*E37,0.05) -> 1.5 | H37: =MROUND(Rates!$B$12*E37,0.05) -> 1.05 | I37: =MROUND(Rates!$B$13*E37,0.05) -> 0.15
A38: 100.01 | B38: 100.01 - 200.00 | C38: 100 | D38: 200 | E38: =(C38+D38)/2 -> 150 | F38: =MROUND(Rates!$B$10*E38,0.05) -> 0.75 | G38: =MROUND(Rates!$B$11*E38,0.05) -> 2.65 | H38: =MROUND(Rates!$B$12*E38,0.05) -> 1.9 | I38: =MROUND(Rates!$B$13*E38,0.05) -> 0.3
A39: 200.01 | B39: 200.01 - 300.00 | C39: 200 | D39: 300 | E39: =(C39+D39)/2 -> 250 | F39: =MROUND(Rates!$B$10*E39,0.05) -> 1.25 | G39: =MROUND(Rates!$B$11*E39,0.05) -> 4.4 | H39: =MROUND(Rates!$B$12*E39,0.05) -> 3.15 | I39: =MROUND(Rates!$B$13*E39,0.05) -> 0.5
A40: 300.01 | B40: 300.01 - 400.00 | C40: 300 | D40: 400 | E40: =(C40+D40)/2 -> 350 | F40: =MROUND(Rates!$B$10*E40,0.05) -> 1.75 | G40: =MROUND(Rates!$B$11*E40,0.05) -> 6.15 | H40: =MROUND(Rates!$B$12*E40,0.05) -> 4.4 | I40: =MROUND(Rates!$B$13*E40,0.05) -> 0.7
A41: 400.01 | B41: 400.01 - 500.00 | C41: 400 | D41: 500 | E41: =(C41+D41)/2 -> 450 | F41: =MROUND(Rates!$B$10*E41,0.05) -> 2.25 | G41: =MROUND(Rates!$B$11*E41,0.05) -> 7.9 | H41: =MROUND(Rates!$B$12*E41,0.05) -> 5.65 | I41: =MROUND(Rates!$B$13*E41,0.05) -> 0.9
A42: 500.01 | B42: 500.01 - 600.00 | C42: 500 | D42: 600 | E42: =(C42+D42)/2 -> 550 | F42: =MROUND(Rates!$B$10*E42,0.05) -> 2.75 | G42: =MROUND(Rates!$B$11*E42,0.05) -> 9.65 | H42: =MROUND(Rates!$B$12*E42,0.05) -> 6.9 | I42: =MROUND(Rates!$B$13*E42,0.05) -> 1.1
A43: 600.01 | B43: 600.01 - 700.00 | C43: 600 | D43: 700 | E43: =(C43+D43)/2 -> 650 | F43: =MROUND(Rates!$B$10*E43,0.05) -> 3.25 | G43: =MROUND(Rates!$B$11*E43,0.05) -> 11.4 | H43: =MROUND(Rates!$B$12*E43,0.05) -> 8.15 | I43: =MROUND(Rates!$B$13*E43,0.05) -> 1.3
...

Sheet How to use
B1: MONTHLY PAYROLL WORKBOOK — HOW TO USE
B3: This workbook turns your monthly payroll image into a calculated payslip run. You only type the blue cells; EPF (KWSP), SOCSO, EIS and PCB are derived automatically.
B5: EACH MONTH — 4 STEPS
B6: 1. Update 'Pay month' (Payroll!B2) and enter each employee's inputs from the image: Basic, Petrol/Incentive/Dishwash/Other allowances, Work Days, Unpaid Days, OT Hours and OT Rate.
B7: 2. Set the three switches per person: Type (Permanent/Part-time/Foreign), 'Apply EPF?' and 'Apply SOCSO+EIS?' (Y/N), and 'Age >= 60?' for the SOCSO category.
B8: 3. Yellow cells are best-effort reads from this month's image — open the image and confirm each one.
B9: 4. Read the results: NET SALARY (take-home) per employee, and EMPLOYER TOTAL COST (gross + employer statutory). The TOTALS row foots every money column.
B11: HOW EACH CONTRIBUTION IS DERIVED
B12: EPF / KWSP — Employee = 11% of EPF wage (rounded up to the next RM). Employer = 13% if total remuneration <= RM5,000, else 12%. Rates live on the 'Rates' sheet.
B13: SOCSO / PERKESO — read from the official RM100-band table (ceiling RM6,000). Category 1 (age < 60): employee 0.5% + employer 1.75% of the band midpoint. Category 2 (age >= 60): employer 1.25% only, employee 0.
B14: EIS — 0.2% each side from the same band table (ceiling RM6,000); not applied at age >= 60.
B15: PCB (income tax, MTD) — an ESTIMATE only: annualised chargeable income (EPF wage x 12 less personal relief RM9,000, EPF relief up to RM4,000, and any 'Extra PCB Relief/yr' you enter for spouse/children) taxed on YA2024/25 resident brackets, less the RM400 rebate, divided by 12. For the exact figure use LHDN e-PCB / e-Jadual PCB and type it into the 'PCB Override' column — the override always wins.
... B33: LHDN individual tax rates (YA2024/2025): https://www.hasil.gov.my/en/individual/
